Workbook

Sheet Cover Page
C10: BD (BDX) Valuation - Group 23
C12: Table of Contents: | G12: Analysts:
C13: Sheet 1: Assumptions Explanation | G13: Arisa Akiyama 1005763238
C14: Sheet 2: Inputs | G14: Sahand Davari 1007130230
C15: Sheet 3: Historical Analysis | G15: Majd Hijazi 1005691020
C16: Sheet 4: Revenue Model | G16: Victoria Magowan 1005152521
C17: Sheet 5: DCF Valuation | G17: Zhenyu Wang 1007072089
C18: Sheet 6: Comparables | G18: Yuchen Zhang 1005727830
C19: Sheet 7: BD Debt
C20: Sheet 8: Cost of Debt
C21: Sheet 9: Cost of Equity
C22: Sheet 10: WACC
C23: Sheet 11-14: BD Financials

Sheet Assumptions Explanation
A1: Ref. # | B1: Explanation of Assumption
A2: 1 | B2: The revenue growth rate is based on each segment's historical growth rate subject to adjustments based on current market conditions and future prospects.
A3: =A2+1 -> 2 | B3: COGS as % of revenue is used in our model since it is relatively stable over the years and it is highly correlated with revenue. There are significant inflation pressures which are expected to increase the prices of raw materials. It is also stated in BD's 2021 Annual Report that costs of raw materials, transportation, construction and other necessary costs for production and distribution of products have increased significantly. These pressures on its supply chain are expected to continue to increase. Therefore, we have adjusted the COGS as a % of revenue to be 3% higher than the historical average from 2016-2021. (BD Annual Report 2021 page 15)
A4: =A3+1 -> 3 | B4: OpEx as % of revenue is used in our model since it is relatively stable over the years and it is highly correlated with revenue. We then adjusted the cost to be a higher percentage as BD's costs are anticipated to increase. Firstly, the EU has recently adopted the EU Medical Device Regulation and the In Vitro Diagnostic Regulation which impose strict requirements for the marketing and sale of medical devices. Compliance and maintenance of medical devices subject to these regulations will increase operating expenses (BD Annual Report 2021 page 18). As mentioned in assumption 2, BD is subject to high inflation pressures which are expected to increase its operating expenses. In addition, the higher transportation and shipping costs as outlined in assumption 2 are expected to increase selling and administrative expenses. Overall, to account for these inflationary pressures on BD's costs, we have increased the OpEx as a % of revenues by 4% compared to the historical average.
A5: =A4+1 -> 4 | B5: D&A as % of revenue is used in our model since it is relatively stable over the years and D&A has a higher correlation with revenue compared to Net PPE.
A6: =A5+1 -> 5 | B6: Statutory US tax rate in 2021 is 21%.
A7: =A6+1 -> 6 | B7: The effective tax rate is much lower than federal statutory tax rate each year due to different foreign income tax on its foreign income (See BD Annual Report 2021 Note 16 - Income Taxes pg 99 and BD Annual Report 2018 Note 16 - Income Taxes pg 97). Since there is very high variability in the effective tax rate and we cannot reasonably predict the changes in the tax rates for each foreign country that BD operates in, we assume the US statutory tax rate of 21%.
A8: =A7+1 -> 7 | B8: It is more reasonable to use change in NWC as a % of revenue since the annual growth rate is very volatile with a high standard deviation.
A9: =A8+1 -> 8 | B9: CAPEX as % of revenue is used in our model since it is relatively stable over the years and it is highly correlated with revenue. We increased CAPEX as a % of revenue by 2% of the previous year as the CAPEX has been increasing each year from 2016 to 2021, with the exception of 2020 which was affected by the COVID-19 pandemic. Furthermore, management has expressed its strategy of geographic expansion which supports our assumption. (BD Annual Report 2021 page 39)
A10: =A9+1 -> 9 | B10: Increased revenue growth by .25 percentage points in bull case supported by an increase in the aging baby boomer population, an increase in chronic disease prevalence, and an assumed increase in elective procesures as virus eliminates all increasing demand.
A11: =A10+1 -> 10 | B11: COGS as % of revenue in the Bull case is decreased by 1 percentage point as supported in the company successfully cutting manufacturing and supplier costs.
A12: =A11+1 -> 11 | B12: OpEx as a % of revenue in the Bull case decreases by 1 percentage point as supported in successfully cutting operational expenses.
A13: =A12+1 -> 12 | B13: We assume that D&A as a % of revenue decreases in the Bull case by one percentage point.
A14: =A13+1 -> 13 | B14: We assume that CAPEX as a % of revenue in the Bull case decreases by 0.2 percentage points. We adjust for a small decrease as we believe that it is unlikely that the firm will decrease capital expenditures based on its increased spending on capital expenditures in the past few years.
... A26: =A25+1 -> 25 | B26: For the BD Interventional Segment, the average of the historical annual revenue growth rate is used as the base for our projections of the annual growth rate in the next five years. However, we remove the annual growth rate in 2019 as it reflects an inflated increase due to the inclusion of revenues from a new acquisition (BD Annual Report 2019 page 28). We believe this segment will continue to grow as the company has invested a consistent amount as capital expenditures into this segment with $120 million, $119 million, and $125million in FY2019, FY2020, and FY2021 respectively (BD Annual Report 2021 page 76). We did not adjust for COVID-19 impacts on revenues as the decrease in the growth rate in 2020 due to COVID-19 related pressures is offset by the increase in the growth rate in FY2021.
A27: =A26+1 -> 26 | B27: We assumed that the terminal growth rate is 2% with a conservative estimate aligned with the target inflation rate of the Federal Reserve . This is below the historical average GDP growth rate of around 3.14% from 1948 until 2021. | C27: https://ycharts.com/indicators/us_inflation_rate
A28: =A27+1 -> 27 | B28: Since the cash flows are discounted to the fiscal year end of the company of September 31, 2021 under our DCF model, we adjust the discounted time period to discount back to January 24, 2022. | C28: https://tradingeconomics.com/united-states/gdp-growth-annual#:~:text=GDP%20Annual%20Growth%20Rate%20in,the%20second%20quarter%20of%202020.
A29: =A28+1 -> 28 | B29: Located comparable companies through Factset, filtering through General Medical Devices in the North American region, with market caps over 10,000,000
A30: =A29+1 -> 29 | B30: Benchmark 10 year American treasury yield as of March 25th, 2022. (see screenshort below) | C30: https://www.bloomberg.com/markets/rates-bonds/government-bonds/us
A31: =A30+1 -> 30 | B31: Risk premium in the US has an average of 5.5% in 2021, where the historical average has been between 5.2%-5.7%. Thus, we believe that a 5.5% estimate is reasonable. | C31: https://www.statista.com/statistics/664840/average-market-risk-premium-usa/#:~:text=The%20average%20market%20risk%20premium,and%205.7%20percent%20since%202011.

Sheet Inputs
B2: Case Number | C2: ='DCF Valuation'!C3 -> 1 | D2: *Linked to "DCF Valuation"
B4: Case Guide
B5: 1 | C5: Base
B6: 2 | C6: Bull
B7: 3 | C7: Bear
B10: =CONCATENATE("Selected: ", CHOOSE($C$2,B20,B30,B41)) -> Selected: Base Case | C10: FY2016A | D10: 2017 | E10: =D10+1 -> 2018 | F10: =E10+1 -> 2019 | G10: =F10+1 -> 2020 | H10: =G10+1 -> 2021 | I10: =H10+1 -> 2022 | J10: =I10+1 -> 2023 | K10: =J10+1 -> 2024 | L10: =K10+1 -> 2025 | M10: =L10+1 -> 2026
B12: Revenue Growth | C12: =CHOOSE($C$2,C22,C32,C43) -> 0 | D12: =CHOOSE($C$2,D22,D32,D43) -> -0.03124249 | E12: =CHOOSE($C$2,E22,E32,E43) -> 0.3216737 | F12: =CHOOSE($C$2,F22,F32,F43) -> 0.081774385 | G12: =CHOOSE($C$2,G22,G32,G43) -> -0.010005784 | H12: =CHOOSE($C$2,H22,H32,H43) -> 0.18291757 | I12: =CHOOSE($C$2,I22,I32,I43) -> -0.017210736 | J12: =CHOOSE($C$2,J22,J32,J43) -> 0.031744318 | ... M12: =CHOOSE($C$2,M22,M32,M43) -> 0.032164629
B13: COGS as a % of Revenue | C13: =CHOOSE($C$2,C23,C33,C44) -> 0.4359529 | D13: =CHOOSE($C$2,D23,D33,D44) -> 0.43099314 | E13: =CHOOSE($C$2,E23,E33,E44) -> 0.42914346 | F13: =CHOOSE($C$2,F23,F33,F44) -> 0.39745518 | G13: =CHOOSE($C$2,G23,G33,G44) -> 0.43874511 | H13: =CHOOSE($C$2,H23,H33,H44) -> 0.42661004 | I13: =CHOOSE($C$2,I23,I33,I44) -> 0.4564833 | J13: =CHOOSE($C$2,J23,J33,J44) -> 0.4564833 | ... M13: =CHOOSE($C$2,M23,M33,M44) -> 0.4564833 | N13: Assumption 2
B14: OpEx as a % of Revenue | C14: =CHOOSE($C$2,C24,C34,C45) -> 0.3070576 | D14: =CHOOSE($C$2,D24,D34,D45) -> 0.30587943 | E14: =CHOOSE($C$2,E24,E34,E45) -> 0.31408371 | F14: =CHOOSE($C$2,F24,F34,F45) -> 0.31197224 | G14: =CHOOSE($C$2,G24,G34,G45) -> 0.31670269 | H14: =CHOOSE($C$2,H24,H34,H45) -> 0.30649941 | I14: =CHOOSE($C$2,I24,I34,I45) -> 0.35036585 | J14: =CHOOSE($C$2,J24,J34,J45) -> 0.35036585 | ... M14: =CHOOSE($C$2,M24,M34,M45) -> 0.35036585 | N14: Assumption 3
B15: D&A as a % of Revenue | C15: =CHOOSE($C$2,C25,C35,C46) -> 0.084114396 | D15: =CHOOSE($C$2,D25,D35,D46) -> 0.077648226 | E15: =CHOOSE($C$2,E25,E35,E46) -> 0.11606081 | F15: =CHOOSE($C$2,F25,F35,F46) -> 0.1231926 | G15: =CHOOSE($C$2,G25,G35,G46) -> 0.11859555 | H15: =CHOOSE($C$2,H25,H35,H46) -> 0.10539313 | I15: =CHOOSE($C$2,I25,I35,I46) -> 0.10416745 | J15: =CHOOSE($C$2,J25,J35,J46) -> 0.10416745 | ... M15: =CHOOSE($C$2,M25,M35,M46) -> 0.10416745 | N15: Assumption 4
B16: CAPEX as a % of Revenue | C16: =CHOOSE($C$2,C26,C36,C47) -> 0.057518225 | D16: =CHOOSE($C$2,D26,D36,D47) -> 0.060117423 | E16: =CHOOSE($C$2,E26,E36,E47) -> 0.055996997 | F16: =CHOOSE($C$2,F26,F36,F47) -> 0.055349913 | G16: =CHOOSE($C$2,G26,G36,G47) -> 0.047321376 | H16: =CHOOSE($C$2,H26,H36,H47) -> 0.060796128 | I16: =CHOOSE($C$2,I26,I36,I47) -> 0.066183344 | J16: =CHOOSE($C$2,J26,J36,J47) -> 0.076183344 | ... M16: =CHOOSE($C$2,M26,M36,M47) -> 0.10618334 | N16: Assumption 8
B17: Change in NWC as % of Revenue | C17: =CHOOSE($C$2,C27,C37,C48) -> 0.03196347 | D17: =CHOOSE($C$2,D27,D37,D48) -> -0.030678905 | E17: =CHOOSE($C$2,E27,E37,E48) -> 0.05612213 | F17: =CHOOSE($C$2,F27,F37,F48) -> -0.021341816 | G17: =CHOOSE($C$2,G27,G37,G48) -> 0.0066016241 | H17: =CHOOSE($C$2,H27,H37,H48) -> 0.016495456 | I17: =CHOOSE($C$2,I27,I37,I48) -> 0.0098603266 | J17: =CHOOSE($C$2,J27,J37,J48) -> 0.0098603266 | ... M17: =CHOOSE($C$2,M27,M37,M48) -> 0.0098603266 | N17: Assumption 7
B18: Effective Tax Rate | C18: =CHOOSE($C$2,C28,C38,C49) -> 0.091247672 | D18: =CHOOSE($C$2,D28,D38,D49) -> -0.12704918 | E18: =CHOOSE($C$2,E28,E38,E49) -> 0.73486786 | F18: =CHOOSE($C$2,F28,F38,F49) -> -0.048469388 | G18: =CHOOSE($C$2,G28,G38,G49) -> 0.11269036 | H18: =CHOOSE($C$2,H28,H38,H49) -> 0.06690455 | I18: =CHOOSE($C$2,I28,I38,I49) -> 0.21 | J18: =CHOOSE($C$2,J28,J38,J49) -> 0.21 | ... M18: =CHOOSE($C$2,M28,M38,M49) -> 0.21 | N18: Assumption 6
B20: Base Case | C20: FY2016A | D20: 2017 | E20: =D20+1 -> 2018 | F20: =E20+1 -> 2019 | G20: =F20+1 -> 2020 | H20: =G20+1 -> 2021 | I20: =H20+1 -> 2022 | J20: =I20+1 -> 2023 | K20: =J20+1 -> 2024 | L20: =K20+1 -> 2025 | M20: =L20+1 -> 2026
B22: Revenue Growth | D22: ='Revenue Model'!D14 -> -0.03124249 | E22: ='Revenue Model'!E14 -> 0.3216737 | F22: ='Revenue Model'!F14 -> 0.081774385 | G22: ='Revenue Model'!G14 -> -0.010005784 | H22: ='Revenue Model'!H14 -> 0.18291757 | I22: ='Revenue Model'!I14 -> -0.017210736 | J22: ='Revenue Model'!J14 -> 0.031744318 | K22: ='Revenue Model'!K14 -> 0.031884958 | ... M22: ='Revenue Model'!M14 -> 0.032164629 | N22: *See tab "Revenue Model" for assumptions
B23: COGS as a % of Revenue | C23: ='Historical Analysis'!C8 -> 0.4359529 | D23: ='Historical Analysis'!D8 -> 0.43099314 | E23: ='Historical Analysis'!E8 -> 0.42914346 | F23: ='Historical Analysis'!F8 -> 0.39745518 | G23: ='Historical Analysis'!G8 -> 0.43874511 | H23: ='Historical Analysis'!H8 -> 0.42661004 | I23: ='Historical Analysis'!$J$8+0.03 -> 0.4564833 | J23: ='Historical Analysis'!$J$8+0.03 -> 0.4564833 | K23: ='Historical Analysis'!$J$8+0.03 -> 0.4564833 | L23: ='Historical Analysis'!$J$8+0.03 -> 0.4564833 | M23: ='Historical Analysis'!$J$8+0.03 -> 0.4564833 | N23: *See tab "Historical Analysis" for assumptions
B24: OpEx as a % of Revenue | C24: ='Historical Analysis'!C11 -> 0.3070576 | D24: ='Historical Analysis'!D11 -> 0.30587943 | E24: ='Historical Analysis'!E11 -> 0.31408371 | F24: ='Historical Analysis'!F11 -> 0.31197224 | G24: ='Historical Analysis'!G11 -> 0.31670269 | H24: ='Historical Analysis'!H11 -> 0.30649941 | I24: ='Historical Analysis'!$J$11+0.04 -> 0.35036585 | J24: ='Historical Analysis'!$J$11+0.04 -> 0.35036585 | K24: ='Historical Analysis'!$J$11+0.04 -> 0.35036585 | L24: ='Historical Analysis'!$J$11+0.04 -> 0.35036585 | M24: ='Historical Analysis'!$J$11+0.04 -> 0.35036585 | N24: *See tab "Historical Analysis" for assumptions
B25: D&A as a % of Revenue | C25: ='Historical Analysis'!C14 -> 0.084114396 | D25: ='Historical Analysis'!D14 -> 0.077648226 | E25: ='Historical Analysis'!E14 -> 0.11606081 | F25: ='Historical Analysis'!F14 -> 0.1231926 | G25: ='Historical Analysis'!G14 -> 0.11859555 | H25: ='Historical Analysis'!H14 -> 0.10539313 | I25: ='Historical Analysis'!$J$14 -> 0.10416745 | J25: ='Historical Analysis'!$J$14 -> 0.10416745 | K25: ='Historical Analysis'!$J$14 -> 0.10416745 | L25: ='Historical Analysis'!$J$14 -> 0.10416745 | M25: ='Historical Analysis'!$J$14 -> 0.10416745 | N25: *See tab "Historical Analysis" for assumptions
B26: CAPEX as a % of Revenue | C26: ='Historical Analysis'!C29 -> 0.057518225 | D26: ='Historical Analysis'!D29 -> 0.060117423 | E26: ='Historical Analysis'!E29 -> 0.055996997 | F26: ='Historical Analysis'!F29 -> 0.055349913 | G26: ='Historical Analysis'!G29 -> 0.047321376 | H26: ='Historical Analysis'!H29 -> 0.060796128 | I26: ='Historical Analysis'!$J$29+0.01 -> 0.066183344 | J26: ='Historical Analysis'!$J$29+0.02 -> 0.076183344 | K26: ='Historical Analysis'!$J$29+0.03 -> 0.086183344 | L26: ='Historical Analysis'!$J$29+0.04 -> 0.096183344 | M26: ='Historical Analysis'!$J$29+0.05 -> 0.10618334 | N26: *See tab "Historical Analysis" for assumptions
B27: Change in NWC as % of Revenue | C27: ='Historical Analysis'!C26 -> 0.03196347 | D27: ='Historical Analysis'!D26 -> -0.030678905 | E27: ='Historical Analysis'!E26 -> 0.05612213 | F27: ='Historical Analysis'!F26 -> -0.021341816 | G27: ='Historical Analysis'!G26 -> 0.0066016241 | H27: ='Historical Analysis'!H26 -> 0.016495456 | I27: ='Historical Analysis'!$J$26 -> 0.0098603266 | J27: ='Historical Analysis'!$J$26 -> 0.0098603266 | K27: ='Historical Analysis'!$J$26 -> 0.0098603266 | L27: ='Historical Analysis'!$J$26 -> 0.0098603266 | M27: ='Historical Analysis'!$J$26 -> 0.0098603266 | N27: *See tab "Historical Analysis" for assumptions
B28: Effective Tax Rate | C28: ='Historical Analysis'!C17 -> 0.091247672 | D28: ='Historical Analysis'!D17 -> -0.12704918 | E28: ='Historical Analysis'!E17 -> 0.73486786 | F28: ='Historical Analysis'!F17 -> -0.048469388 | G28: ='Historical Analysis'!G17 -> 0.11269036 | H28: ='Historical Analysis'!H17 -> 0.06690455 | I28: 0.21 | J28: 0.21 | K28: 0.21 | L28: 0.21 | M28: 0.21 | N28: *See tab "Historical Analysis" for assumptions
B30: Bull Case | C30: FY2016A | D30: 2017 | E30: =D30+1 -> 2018 | F30: =E30+1 -> 2019 | G30: =F30+1 -> 2020 | H30: =G30+1 -> 2021 | I30: =H30+1 -> 2022 | J30: =I30+1 -> 2023 | K30: =J30+1 -> 2024 | L30: =K30+1 -> 2025 | M30: =L30+1 -> 2026
B32: Revenue Growth | D32: ='Revenue Model'!D29 -> -0.03124249 | E32: ='Revenue Model'!E29 -> 0.3216737 | F32: ='Revenue Model'!F29 -> 0.081774385 | G32: ='Revenue Model'!G29 -> -0.010005784 | H32: ='Revenue Model'!H29 -> 0.18291757 | I32: =I22+0.0025 -> -0.014710736 | J32: =J22+0.0025 -> 0.034244318 | K32: =K22+0.0025 -> 0.034384958 | L32: =L22+0.0025 -> 0.034525074 | M32: =M22+0.0025 -> 0.034664629 | N32: Assumption 9
B33: COGS as a % of Revenue | C33: ='Historical Analysis'!C8 -> 0.4359529 | D33: ='Historical Analysis'!D8 -> 0.43099314 | E33: ='Historical Analysis'!E8 -> 0.42914346 | F33: ='Historical Analysis'!F8 -> 0.39745518 | G33: ='Historical Analysis'!G8 -> 0.43874511 | H33: ='Historical Analysis'!H8 -> 0.42661004 | I33: =I23-0.01 -> 0.4464833 | J33: =J23-0.01 -> 0.4464833 | K33: =K23-0.01 -> 0.4464833 | L33: =L23-0.01 -> 0.4464833 | M33: =M23-0.01 -> 0.4464833 | N33: Assumption 10
B34: OpEx as a % of Revenue | C34: ='Historical Analysis'!C11 -> 0.3070576 | D34: ='Historical Analysis'!D11 -> 0.30587943 | E34: ='Historical Analysis'!E11 -> 0.31408371 | F34: ='Historical Analysis'!F11 -> 0.31197224 | G34: ='Historical Analysis'!G11 -> 0.31670269 | H34: ='Historical Analysis'!H11 -> 0.30649941 | I34: =I24-0.01 -> 0.34036585 | J34: =J24-0.01 -> 0.34036585 | K34: =K24-0.01 -> 0.34036585 | L34: =L24-0.01 -> 0.34036585 | M34: =M24-0.01 -> 0.34036585 | N34: Assumption 11
B35: D&A as a % of Revenue | C35: ='Historical Analysis'!C14 -> 0.084114396 | D35: ='Historical Analysis'!D14 -> 0.077648226 | E35: ='Historical Analysis'!E14 -> 0.11606081 | F35: ='Historical Analysis'!F14 -> 0.1231926 | G35: ='Historical Analysis'!G14 -> 0.11859555 | H35: ='Historical Analysis'!H14 -> 0.10539313 | I35: =I25-0.01 -> 0.094167451 | J35: =J25-0.01 -> 0.094167451 | K35: =K25-0.01 -> 0.094167451 | L35: =L25-0.01 -> 0.094167451 | M35: =M25-0.01 -> 0.094167451 | N35: Assumption 12
B36: CAPEX as a % of Revenue | C36: ='Historical Analysis'!C29 -> 0.057518225 | D36: ='Historical Analysis'!D29 -> 0.060117423 | E36: ='Historical Analysis'!E29 -> 0.055996997 | F36: ='Historical Analysis'!F29 -> 0.055349913 | G36: ='Historical Analysis'!G29 -> 0.047321376 | H36: ='Historical Analysis'!H29 -> 0.060796128 | I36: =I26-0.002 -> 0.064183344 | J36: =J26-0.002 -> 0.074183344 | K36: =K26-0.002 -> 0.084183344 | L36: =L26-0.002 -> 0.094183344 | M36: =M26-0.002 -> 0.10418334 | N36: Assumption 13
B37: Change in NWC as % of Revenue | C37: ='Historical Analysis'!C26 -> 0.03196347 | D37: ='Historical Analysis'!D26 -> -0.030678905 | E37: ='Historical Analysis'!E26 -> 0.05612213 | F37: ='Historical Analysis'!F26 -> -0.021341816 | G37: ='Historical Analysis'!G26 -> 0.0066016241 | H37: ='Historical Analysis'!H26 -> 0.016495456 | I37: =I27+0.005 -> 0.014860327 | J37: =J27+0.005 -> 0.014860327 | K37: =K27+0.005 -> 0.014860327 | L37: =L27+0.005 -> 0.014860327 | M37: =M27+0.005 -> 0.014860327 | N37: Assumption 14
B38: Effective Tax Rate | C38: ='Historical Analysis'!C17 -> 0.091247672 | D38: ='Historical Analysis'!D17 -> -0.12704918 | E38: ='Historical Analysis'!E17 -> 0.73486786 | F38: ='Historical Analysis'!F17 -> -0.048469388 | G38: ='Historical Analysis'!G17 -> 0.11269036 | H38: ='Historical Analysis'!H17 -> 0.06690455 | I38: =I28-0.02 -> 0.19 | J38: =J28-0.02 -> 0.19 | K38: =K28-0.02 -> 0.19 | L38: =L28-0.02 -> 0.19 | M38: =M28-0.02 -> 0.19 | N38: Assumption 15
B41: Bear Case | C41: FY2016A | D41: 2017 | E41: =D41+1 -> 2018 | F41: =E41+1 -> 2019 | G41: =F41+1 -> 2020 | H41: =G41+1 -> 2021 | I41: =H41+1 -> 2022 | J41: =I41+1 -> 2023 | K41: =J41+1 -> 2024 | L41: =K41+1 -> 2025 | M41: =L41+1 -> 2026
B43: Revenue Growth | D43: ='Revenue Model'!D29 -> -0.03124249 | E43: ='Revenue Model'!E29 -> 0.3216737 | F43: ='Revenue Model'!F29 -> 0.081774385 | G43: ='Revenue Model'!G29 -> -0.010005784 | H43: ='Revenue Model'!H29 -> 0.18291757 | I43: =I22-0.0025 -> -0.019710736 | J43: =J22-0.0025 -> 0.029244318 | K43: =K22-0.0025 -> 0.029384958 | L43: =L22-0.0025 -> 0.029525074 | M43: =M22-0.0025 -> 0.029664629 | N43: Assumption 16
B44: COGS as a % of Revenue | C44: ='Historical Analysis'!C8 -> 0.4359529 | D44: ='Historical Analysis'!D8 -> 0.43099314 | E44: ='Historical Analysis'!E8 -> 0.42914346 | F44: ='Historical Analysis'!F8 -> 0.39745518 | G44: ='Historical Analysis'!G8 -> 0.43874511 | H44: ='Historical Analysis'!H8 -> 0.42661004 | I44: =I23+0.03 -> 0.4864833 | J44: =J23+0.03 -> 0.4864833 | K44: =K23+0.03 -> 0.4864833 | L44: =L23+0.03 -> 0.4864833 | M44: =M23+0.03 -> 0.4864833 | N44: Assumption 17
B45: OpEx as a % of Revenue | C45: ='Historical Analysis'!C11 -> 0.3070576 | D45: ='Historical Analysis'!D11 -> 0.30587943 | E45: ='Historical Analysis'!E11 -> 0.31408371 | F45: ='Historical Analysis'!F11 -> 0.31197224 | G45: ='Historical Analysis'!G11 -> 0.31670269 | H45: ='Historical Analysis'!H11 -> 0.30649941 | I45: =I24+0.02 -> 0.37036585 | J45: =J24+0.02 -> 0.37036585 | K45: =K24+0.02 -> 0.37036585 | L45: =L24+0.02 -> 0.37036585 | M45: =M24+0.02 -> 0.37036585 | N45: Assumption 18
B46: D&A as a % of Revenue | C46: ='Historical Analysis'!C14 -> 0.084114396 | D46: ='Historical Analysis'!D14 -> 0.077648226 | E46: ='Historical Analysis'!E14 -> 0.11606081 | F46: ='Historical Analysis'!F14 -> 0.1231926 | G46: ='Historical Analysis'!G14 -> 0.11859555 | H46: ='Historical Analysis'!H14 -> 0.10539313 | I46: =I25+0.01 -> 0.11416745 | J46: =J25+0.01 -> 0.11416745 | K46: =K25+0.01 -> 0.11416745 | L46: =L25+0.01 -> 0.11416745 | M46: =M25+0.01 -> 0.11416745 | N46: Assumption 19
B47: CAPEX as a % of Revenue | C47: ='Historical Analysis'!C29 -> 0.057518225 | D47: ='Historical Analysis'!D29 -> 0.060117423 | E47: ='Historical Analysis'!E29 -> 0.055996997 | F47: ='Historical Analysis'!F29 -> 0.055349913 | G47: ='Historical Analysis'!G29 -> 0.047321376 | H47: ='Historical Analysis'!H29 -> 0.060796128 | I47: =I26+0.02 -> 0.086183344 | J47: =J26+0.02 -> 0.096183344 | K47: =K26+0.02 -> 0.10618334 | L47: =L26+0.02 -> 0.11618334 | M47: =M26+0.02 -> 0.12618334 | N47: Assumption 20
B48: Change in NWC as % of Revenue | C48: ='Historical Analysis'!C26 -> 0.03196347 | D48: ='Historical Analysis'!D26 -> -0.030678905 | E48: ='Historical Analysis'!E26 -> 0.05612213 | F48: ='Historical Analysis'!F26 -> -0.021341816 | G48: ='Historical Analysis'!G26 -> 0.0066016241 | H48: ='Historical Analysis'!H26 -> 0.016495456 | I48: =I27-0.005 -> 0.0048603266 | J48: =J27-0.005 -> 0.0048603266 | K48: =K27-0.005 -> 0.0048603266 | L48: =L27-0.005 -> 0.0048603266 | M48: =M27-0.005 -> 0.0048603266 | N48: Assumption 21
B49: Effective Tax Rate | C49: ='Historical Analysis'!C17 -> 0.091247672 | D49: ='Historical Analysis'!D17 -> -0.12704918 | E49: ='Historical Analysis'!E17 -> 0.73486786 | F49: ='Historical Analysis'!F17 -> -0.048469388 | G49: ='Historical Analysis'!G17 -> 0.11269036 | H49: ='Historical Analysis'!H17 -> 0.06690455 | I49: =I28+0.01 -> 0.22 | J49: =J28+0.01 -> 0.22 | K49: =K28+0.01 -> 0.22 | L49: =L28+0.01 -> 0.22 | M49: =M28+0.01 -> 0.22 | N49: Assumption 22

Sheet Historical Analysis
B2: Analysis | C2: FY2016A | D2: 2017 | E2: =D2+1 -> 2018 | F2: =E2+1 -> 2019 | G2: =F2+1 -> 2020 | H2: =G2+1 -> 2021 | J2: Average | K2: Standard Deviation | L2: Correl. with Revenue
B3: (millions of dollars)
B4: From Income Statement
B5: Revenue | C5: ='Income Statement'!B11 -> 12483 | D5: ='Income Statement'!C11 -> 12093 | E5: ='Income Statement'!D11 -> 15983 | F5: ='Income Statement'!E11 -> 17290 | G5: ='Income Statement'!F11 -> 17117 | H5: ='Income Statement'!G11 -> 20248 | L5: =CORREL(C5:H5,C5:H5) -> 1
B6: Revenue Annual Growth Rate | D6: =D5/C5-1 -> -0.03124249 | E6: =E5/D5-1 -> 0.3216737 | F6: =F5/E5-1 -> 0.081774385 | G6: =G5/F5-1 -> -0.010005784 | H6: =H5/G5-1 -> 0.18291757 | J6: =AVERAGE(C6:H6) -> 0.10902347 | K6: =_xlfn.STDEV.S(C6:H6) -> 0.14600126 | L6: =CORREL(D6:H6,D6:H6) -> 1
B7: COGS | C7: ='Income Statement'!B13 -> 5442 | D7: ='Income Statement'!C13 -> 5212 | E7: ='Income Statement'!D13 -> 6859 | F7: ='Income Statement'!E13 -> 6872 | G7: ='Income Statement'!F13 -> 7510 | H7: ='Income Statement'!G13 -> 8638
B8: COGS as a % of Revenue | C8: =C7/C5 -> 0.4359529 | D8: =D7/D5 -> 0.43099314 | E8: =E7/E5 -> 0.42914346 | F8: =F7/F5 -> 0.39745518 | G8: =G7/G5 -> 0.43874511 | H8: =H7/H5 -> 0.42661004 | J8: =AVERAGE(C8:H8) -> 0.4264833 | K8: =_xlfn.STDEV.S(C8:H8) -> 0.014900257 | L8: =CORREL(C5:H5,C7:H7) -> 0.98216784
B9: COGS Annual Growth Rate | D9: =D7/C7-1 -> -0.042263874 | E9: =E7/D7-1 -> 0.31600153 | F9: =F7/E7-1 -> 0.00189532 | G9: =G7/F7-1 -> 0.092840512 | H9: =H7/G7-1 -> 0.15019973 | J9: =AVERAGE(C9:H9) -> 0.10373465 | K9: =_xlfn.STDEV.S(C9:H9) -> 0.14055402 | L9: =CORREL(D6:H6,D9:H9) -> 0.89082207
B10: OpEx | C10: ='Income Statement'!B18 -> 3833 | D10: ='Income Statement'!C18 -> 3699 | E10: ='Income Statement'!D18 -> 5020 | F10: ='Income Statement'!E18 -> 5394 | G10: ='Income Statement'!F18 -> 5421 | H10: ='Income Statement'!G18 -> 6206
B11: OpEx as a % of Revenue | C11: =C10/C5 -> 0.3070576 | D11: =D10/D5 -> 0.30587943 | E11: =E10/E5 -> 0.31408371 | F11: =F10/F5 -> 0.31197224 | G11: =G10/G5 -> 0.31670269 | H11: =H10/H5 -> 0.30649941 | J11: =AVERAGE(C11:H11) -> 0.31036585 | K11: =_xlfn.STDEV.S(C11:H11) -> 0.0045294682 | L11: =CORREL(C5:H5,C10:H10) -> 0.99728694
B12: OpEx Annual Growth Rate | D12: =D11/C11-1 -> -0.0038369477 | E12: =E11/D11-1 -> 0.026821939 | F12: =F11/E11-1 -> -0.0067226525 | G12: =G11/F11-1 -> 0.015163064 | H12: =H11/G11-1 -> -0.032217237 | J12: =AVERAGE(C12:H12) -> -0.00015836696 | K12: =_xlfn.STDEV.S(C12:H12) -> 0.022622313 | L12: =CORREL(D12:H12,D6:H6) -> 0.16951529
B13: D&A | C13: ='Income Statement'!B14 -> 1050 | D13: ='Income Statement'!C14 -> 939 | E13: ='Income Statement'!D14 -> 1855 | F13: ='Income Statement'!E14 -> 2130 | G13: ='Income Statement'!F14 -> 2030 | H13: ='Income Statement'!G14 -> 2134
B14: D&A as a % of Revenue | C14: =C13/C5 -> 0.084114396 | D14: =D13/D5 -> 0.077648226 | E14: =E13/E5 -> 0.11606081 | F14: =F13/F5 -> 0.1231926 | G14: =G13/G5 -> 0.11859555 | H14: =H13/H5 -> 0.10539313 | J14: =AVERAGE(C14:H14) -> 0.10416745 | K14: =_xlfn.STDEV.S(C14:H14) -> 0.019070788 | L14: =CORREL(C5:H5,C13:H13) -> 0.93762477
B15: D&A as a % of Net PPE | C15: =C13/C20 -> 0.26916175 | D15: =D13/D20 -> 0.20245796 | E15: =E13/E20 -> 0.34511628 | F15: =F13/F20 -> 0.37639159 | G15: =G13/G20 -> 0.32013878 | H15: =H13/H20 -> 0.31203392 | J15: =AVERAGE(C15:H15) -> 0.30421671 | K15: =_xlfn.STDEV.S(C15:H15) -> 0.061286708 | L15: =CORREL(C20:H20,C13:H13) -> 0.87720662
B16: D&A Annual Growth Rate | D16: =D13/C13-1 -> -0.10571429 | E16: =E13/D13-1 -> 0.97550586 | F16: =F13/E13-1 -> 0.14824798 | G16: =G13/F13-1 -> -0.046948357 | H16: =H13/G13-1 -> 0.051231527 | J16: =AVERAGE(C16:H16) -> 0.20446454 | K16: =_xlfn.STDEV.S(C16:H16) -> 0.44174787 | L16: =CORREL(D16:H16,D6:H6) -> 0.88224411
B17: Effective Tax Rate | C17: ='Income Statement'!B42/'Income Statement'!B41 -> 0.091247672 | D17: ='Income Statement'!C42/'Income Statement'!C41 -> -0.12704918 | E17: ='Income Statement'!D42/'Income Statement'!D41 -> 0.73486786 | F17: ='Income Statement'!E42/'Income Statement'!E41 -> -0.048469388 | G17: ='Income Statement'!F42/'Income Statement'!F41 -> 0.11269036 | H17: ='Income Statement'!G42/'Income Statement'!G41 -> 0.06690455 | J17: =AVERAGE(C17:H17) -> 0.13836531 | K17: =_xlfn.STDEV.S(C17:H17) -> 0.30631789 | L17: =CORREL(C5:H5,C17:H17) -> 0.12984164
B19: From Balance Sheet
B20: Net PPE | C20: ='Balance Sheet'!B26 -> 3901 | D20: ='Balance Sheet'!C26 -> 4638 | E20: ='Balance Sheet'!D26 -> 5375 | F20: ='Balance Sheet'!E26 -> 5659 | G20: ='Balance Sheet'!F26 -> 6341 | H20: ='Balance Sheet'!G26 -> 6839
B21: Net PPE as a % of Revenue | C21: =C20/C5 -> 0.31250501 | D21: =D20/D5 -> 0.38352766 | E21: =E20/E5 -> 0.33629481 | F21: =F20/F5 -> 0.32729902 | G21: =G20/G5 -> 0.37045043 | H21: =H20/H5 -> 0.33776175 | J21: =AVERAGE(C21:H21) -> 0.34463978 | K21: =_xlfn.STDEV.S(C21:H21) -> 0.026939741 | L21: =CORREL(C5:H5,C20:H20) -> 0.93930205
B22: Net PPE Annual Growth Rate | D22: =D20/C20-1 -> 0.18892592 | E22: =E20/D20-1 -> 0.1589047 | F22: =F20/E20-1 -> 0.052837209 | G22: =G20/F20-1 -> 0.12051599 | H22: =H20/G20-1 -> 0.078536508 | J22: =AVERAGE(C22:H22) -> 0.11994407 | K22: =_xlfn.STDEV.S(C22:H22) -> 0.05588978 | L22: =CORREL(D22:H22,$D$6:$H$6) -> -0.082416501
B24: From Cash Flow Statement
B25: Change in NWC | C25: ='Cash Flow Statement'!B20 -> 399 | D25: ='Cash Flow Statement'!C20 -> -371 | E25: ='Cash Flow Statement'!D20 -> 897 | F25: ='Cash Flow Statement'!E20 -> -369 | G25: ='Cash Flow Statement'!F20 -> 113 | H25: ='Cash Flow Statement'!G20 -> 334
B26: Change in NWC as % of Revenue | C26: =C25/C5 -> 0.03196347 | D26: =D25/D5 -> -0.030678905 | E26: =E25/E5 -> 0.05612213 | F26: =F25/F5 -> -0.021341816 | G26: =G25/G5 -> 0.0066016241 | H26: =H25/H5 -> 0.016495456 | J26: =AVERAGE(C26:H26) -> 0.0098603266 | K26: =_xlfn.STDEV.S(C26:H26) -> 0.032558718 | L26: =CORREL(C5:H5,C25:H25) -> 0.16181875
B27: Change in NWC Annual Growth Rate | D27: =D25/C25-1 -> -1.9298246 | E27: =E25/D25-1 -> -3.4177898 | F27: =F25/E25-1 -> -1.4113712 | G27: =G25/F25-1 -> -1.3062331 | H27: =H25/G25-1 -> 1.9557522 | J27: =AVERAGE(C27:H27) -> -1.2218933 | K27: =_xlfn.STDEV.S(C27:H27) -> 1.9661876 | L27: =CORREL(D27:H27,$D$6:$H$6) -> -0.1024573
B28: CAPEX | C28: =-'Cash Flow Statement'!B26 -> 718 | D28: =-'Cash Flow Statement'!C26 -> 727 | E28: =-'Cash Flow Statement'!D26 -> 895 | F28: =-'Cash Flow Statement'!E26 -> 957 | G28: =-'Cash Flow Statement'!F26 -> 810 | H28: =-'Cash Flow Statement'!G26 -> 1231
B29: CAPEX as a % of Revenue | C29: =C28/C5 -> 0.057518225 | D29: =D28/D5 -> 0.060117423 | E29: =E28/E5 -> 0.055996997 | F29: =F28/F5 -> 0.055349913 | G29: =G28/G5 -> 0.047321376 | H29: =H28/H5 -> 0.060796128 | J29: =AVERAGE(C29:H29) -> 0.056183344 | K29: =_xlfn.STDEV.S(C29:H29) -> 0.004853874 | L29: =CORREL(C5:H5,C28:H28) -> 0.90119713
B30: CAPEX as a % of Net PPE | C30: =C28/C20 -> 0.18405537 | D30: =D28/D20 -> 0.1567486 | E30: =E28/E20 -> 0.16651163 | F30: =F28/F20 -> 0.16911115 | G30: =G28/G20 -> 0.1277401 | H30: =H28/H20 -> 0.17999708 | J30: =AVERAGE(C30:H30) -> 0.16402732 | K30: =_xlfn.STDEV.S(C30:H30) -> 0.020287508 | L30: =CORREL(C20:H20,C28:H28) -> 0.78804225
B31: CAPEX Annual Growth Rate | D31: =D28/C28-1 -> 0.012534819 | E31: =E28/D28-1 -> 0.23108666 | F31: =F28/E28-1 -> 0.069273743 | G31: =G28/F28-1 -> -0.15360502 | H31: =H28/G28-1 -> 0.51975309 | J31: =AVERAGE(C31:H31) -> 0.13580866 | K31: =_xlfn.STDEV.S(C31:H31) -> 0.2548896 | L31: =CORREL(C6:H6,C31:H31) -> 0.68646471

Sheet Revenue Model
B2: Revenue Build | C2: FY2016A | D2: 2017 | E2: =D2+1 -> 2018 | F2: =E2+1 -> 2019 | G2: =F2+1 -> 2020 | H2: =G2+1 -> 2021 | I2: =H2+1 -> 2022 | J2: =I2+1 -> 2023 | K2: =J2+1 -> 2024 | L2: =K2+1 -> 2025 | M2: =L2+1 -> 2026
B3: (millions of dollars)
B4: Medical | C4: ='Segments '!F6 -> 8654 | D4: ='Segments '!G6 -> 8105 | E4: ='Segments '!H6 -> 8616 | F4: ='Segments '!I6 -> 9064 | G4: ='Segments '!J6 -> 8680 | H4: ='Segments '!K6 -> 9479 | I4: =H4*(1+I5) -> 8487.5266 | J4: =I4*(1+J5) -> 8638.4259 | K4: =J4*(1+K5) -> 8792.0081 | L4: =K4*(1+L5) -> 8948.3207 | M4: =L4*(1+M5) -> 9107.4124
B5: Annual Growth Rate | D5: =D4/C4-1 -> -0.063438872 | E5: =E4/D4-1 -> 0.063047502 | F5: =F4/E4-1 -> 0.051996286 | G5: =G4/F4-1 -> -0.042365402 | H5: =H4/G4-1 -> 0.092050691 | I5: =((9479-1160)*(1+J20))/H4-1 -> -0.10459683 | J5: =$J$20*(9479-1160)/9479 -> 0.017778947 | K5: =$J$20*(9479-1160)/9479 -> 0.017778947 | L5: =$J$20*(9479-1160)/9479 -> 0.017778947 | M5: =$J$20*(9479-1160)/9479 -> 0.017778947 | N5: Assumption 23
B6: % of Total Revenues | D6: =D4/D13 -> 0.67022244 | E6: =E4/E13 -> 0.53907276 | F6: =F4/F13 -> 0.52423366 | G6: =G4/G13 -> 0.50709821 | H6: =H4/H13 -> 0.468145 | I6: =I4/I13 -> 0.42651923 | J6: =J4/J13 -> 0.420746 | K6: =K4/K13 -> 0.41499434 | ... M6: =M4/M13 -> 0.40356164
B7: Life Sciences | C7: ='Segments '!F7 -> 3829 | D7: ='Segments '!G7 -> 3988 | E7: ='Segments '!H7 -> 4330 | F7: ='Segments '!I7 -> 4300 | G7: ='Segments '!J7 -> 4675 | H7: ='Segments '!K7 -> 6530 | I7: =H7*(1+I8) -> 6992.7874 | J7: =I7*(1+J8) -> 7285.7211 | K7: =J7*(1+K8) -> 7590.9261 | L7: =K7*(1+L8) -> 7908.9164 | M7: =L7*(1+M8) -> 8240.2276
B8: Annual Growth Rate | D8: =D7/C7-1 -> 0.041525202 | E8: =E7/D7-1 -> 0.085757272 | F8: =F7/E7-1 -> -0.0069284065 | G8: =G7/F7-1 -> 0.087209302 | H8: =H7/G7-1 -> 0.39679144 | I8: =J23-0.05 -> 0.070870963 | J8: =AVERAGE($D$8:$G$8)-0.01 -> 0.041890843 | K8: =AVERAGE($D$8:$G$8)-0.01 -> 0.041890843 | L8: =AVERAGE($D$8:$G$8)-0.01 -> 0.041890843 | M8: =AVERAGE($D$8:$G$8)-0.01 -> 0.041890843 | N8: Assumption 24
B9: % of Total Revenues | D9: =D7/D13 -> 0.32977756 | E9: =E7/E13 -> 0.27091284 | F9: =F7/F13 -> 0.24869867 | G9: =G7/G13 -> 0.27312029 | H9: =H7/H13 -> 0.32250099 | I9: =I7/I13 -> 0.35140488 | J9: =J7/J13 -> 0.35486071 | K9: =K7/K13 -> 0.35830169 | ... M9: =M7/M13 -> 0.36513552
B10: Interventional | C10: 0 | D10: 0 | E10: ='Segments '!H8 -> 3037 | F10: ='Segments '!I8 -> 3926 | G10: ='Segments '!J8 -> 3762 | H10: ='Segments '!K8 -> 4239 | I10: =H10*(1+I11) -> 4419.203 | J10: =I10*(1+J11) -> 4607.0665 | K10: =J10*(1+K11) -> 4802.9163 | L10: =K10*(1+L11) -> 5007.0918 | M10: =L10*(1+M11) -> 5219.9469
B11: Annual Growth Rate | D11: n/a | E11: n/a | F11: =F10/E10-1 -> 0.29272308 | G11: =G10/F10-1 -> -0.041772797 | H11: =H10/G10-1 -> 0.12679426 | I11: =AVERAGE($G$11:$H$11) -> 0.042510731 | J11: =AVERAGE($G$11:$H$11) -> 0.042510731 | K11: =AVERAGE($G$11:$H$11) -> 0.042510731 | L11: =AVERAGE($G$11:$H$11) -> 0.042510731 | M11: =AVERAGE($G$11:$H$11) -> 0.042510731 | N11: Assumption 25
B12: % of Total Revenues | D12: n/a | E12: =E10/E13 -> 0.19001439 | F12: =F10/F13 -> 0.22706767 | G12: =G10/G13 -> 0.2197815 | H12: =H10/H13 -> 0.20935401 | I12: =I10/I13 -> 0.22207589 | J12: =J10/J13 -> 0.22439329 | K12: =K10/K13 -> 0.22670396 | L12: =L10/L13 -> 0.22900734 | M12: =M10/M13 -> 0.23130284
B13: Total Revenue | C13: =C4+C7+C10 -> 12483 | D13: =D4+D7+D10 -> 12093 | E13: =E4+E7+E10 -> 15983 | F13: =F4+F7+F10 -> 17290 | G13: =G4+G7+G10 -> 17117 | H13: =H4+H7+H10 -> 20248 | I13: =I4+I7+I10 -> 19899.517 | J13: =J4+J7+J10 -> 20531.214 | ... M13: =M4+M7+M10 -> 22567.587
B14: Annual Growth Rate | D14: =D13/C13-1 -> -0.03124249 | E14: =E13/D13-1 -> 0.3216737 | F14: =F13/E13-1 -> 0.081774385 | G14: =G13/F13-1 -> -0.010005784 | H14: =H13/G13-1 -> 0.18291757 | I14: =I13/H13-1 -> -0.017210736 | J14: =J13/I13-1 -> 0.031744318 | K14: =K13/J13-1 -> 0.031884958 | ... M14: =M13/L13-1 -> 0.032164629 | N14: Assumption 1
B17: Analysis | C17: FY2016A | D17: 2017 | E17: =D17+1 -> 2018 | F17: =E17+1 -> 2019 | G17: =F17+1 -> 2020 | H17: =G17+1 -> 2021 | J17: Average | K17: Standard Deviation
B18: (millions of dollars)
B19: Medical | C19: ='Segments '!$F$6 -> 8654 | D19: ='Segments '!$G$6 -> 8105 | E19: ='Segments '!$H$6 -> 8616 | F19: ='Segments '!$I$6 -> 9064 | G19: ='Segments '!$J$6 -> 8680 | H19: ='Segments '!$K$6 -> 9479
B20: Annual Growth Rate | D20: =D19/C19-1 -> -0.063438872 | E20: =E19/D19-1 -> 0.063047502 | F20: =F19/E19-1 -> 0.051996286 | G20: =G19/F19-1 -> -0.042365402 | H20: =H19/G19-1 -> 0.092050691 | J20: =AVERAGE(C20:H20) -> 0.020258041 | K20: =_xlfn.STDEV.S(C20:H20) -> 0.068773737
B21: % of Total Revenues | D21: =D19/D28 -> 0.67022244 | E21: =E19/E28 -> 0.53907276 | F21: =F19/F28 -> 0.52423366 | G21: =G19/G28 -> 0.50709821 | H21: =H19/H28 -> 0.468145
B22: Life Sciences | C22: ='Segments '!$F$7 -> 3829 | D22: ='Segments '!$G$7 -> 3988 | E22: ='Segments '!$H$7 -> 4330 | F22: ='Segments '!$I$7 -> 4300 | G22: ='Segments '!$J$7 -> 4675 | H22: ='Segments '!$K$7 -> 6530
B23: Annual Growth Rate | D23: =D22/C22-1 -> 0.041525202 | E23: =E22/D22-1 -> 0.085757272 | F23: =F22/E22-1 -> -0.0069284065 | G23: =G22/F22-1 -> 0.087209302 | H23: =H22/G22-1 -> 0.39679144 | J23: =AVERAGE(C23:H23) -> 0.12087096 | K23: =_xlfn.STDEV.S(C23:H23) -> 0.15900206
B24: % of Total Revenues | D24: =D22/D28 -> 0.32977756 | E24: =E22/E28 -> 0.27091284 | F24: =F22/F28 -> 0.24869867 | G24: =G22/G28 -> 0.27312029 | H24: =H22/H28 -> 0.32250099
B25: Interventional | C25: 0 | D25: 0 | E25: ='Segments '!$H$8 -> 3037 | F25: ='Segments '!$I$8 -> 3926 | G25: ='Segments '!$J$8 -> 3762 | H25: ='Segments '!$K$8 -> 4239
B26: Annual Growth Rate | F26: =F25/E25-1 -> 0.29272308 | G26: =G25/F25-1 -> -0.041772797 | H26: =H25/G25-1 -> 0.12679426 | J26: =AVERAGE(C26:H26) -> 0.12591485 | K26: =_xlfn.STDEV.S(C26:H26) -> 0.16724967
B27: % of Total Revenues | E27: =E25/E28 -> 0.19001439 | F27: =F25/F28 -> 0.22706767 | G27: =G25/G28 -> 0.2197815 | H27: =H25/H28 -> 0.20935401
C28: =C19+C22+C25 -> 12483 | D28: =D19+D22+D25 -> 12093 | E28: =E19+E22+E25 -> 15983 | F28: =F19+F22+F25 -> 17290 | G28: =G19+G22+G25 -> 17117 | H28: =H19+H22+H25 -> 20248
B29: Annual Growth Rate | D29: =D28/C28-1 -> -0.03124249 | E29: =E28/D28-1 -> 0.3216737 | F29: =F28/E28-1 -> 0.081774385 | G29: =G28/F28-1 -> -0.010005784 | H29: =H28/G28-1 -> 0.18291757 | J29: =AVERAGE(C29:H29) -> 0.10902347 | K29: =_xlfn.STDEV.S(C29:H29) -> 0.14600126

Sheet DCF Valuation
B2: Scenarios & Other Inputs
B3: Case Number | C3: 1
B4: Selected Case | C4: {=_xlfn.IFS(C3=1, "Base", C3=2, "Bull", C3=3, "Bear")} -> Base
B5: Risk Free Rate | C5: 0.0247 | D5: Assumption 29
B6: Beta | C6: ='Cost of Equity'!X19 -> 0.66554845
B7: Cost of Equity | C7: =WACC!B7 -> 0.061305165
B8: Cost of Debt | C8: =WACC!B5 -> 0.024109514
B9: Terminal Growth Rate | C9: 0.02
B10: Tax Rate | C10: 0.21
B11: WACC | C11: =WACC!E7 -> 0.052902418
B13: Case Guide
B14: 1 | C14: Base
B15: 2 | C15: Bull
B16: 3 | C16: Bear
B18: DCF Projections
B19: FY Ending September | J19: 1 | K19: 2 | L19: 3 | M19: 4 | N19: 5
B20: FCF | D20: FY2016A | E20: 2017 | F20: =E20+1 -> 2018 | G20: =F20+1 -> 2019 | H20: =G20+1 -> 2020 | I20: =H20+1 -> 2021 | J20: =I20+1 -> 2022 | K20: =J20+1 -> 2023 | L20: =K20+1 -> 2024 | M20: =L20+1 -> 2025 | N20: =M20+1 -> 2026
B21: (millions of dollars)
B22: Revenue | D22: ='Revenue Model'!C13 -> 12483 | E22: ='Revenue Model'!D13 -> 12093 | F22: ='Revenue Model'!E13 -> 15983 | G22: ='Revenue Model'!F13 -> 17290 | H22: ='Revenue Model'!G13 -> 17117 | I22: =H22*(1+Inputs!H12) -> 20248 | J22: =I22*(1+Inputs!I12) -> 19899.517 | K22: =J22*(1+Inputs!J12) -> 20531.214 | L22: =K22*(1+Inputs!K12) -> 21185.85 | M22: =L22*(1+Inputs!L12) -> 21864.329 | N22: =M22*(1+Inputs!M12) -> 22567.587
B23: COGS | D23: ='DCF Valuation'!D22*Inputs!C23 -> 5442 | E23: ='DCF Valuation'!E22*Inputs!D23 -> 5212 | F23: ='DCF Valuation'!F22*Inputs!E23 -> 6859 | G23: ='DCF Valuation'!G22*Inputs!F23 -> 6872 | H23: ='DCF Valuation'!H22*Inputs!G23 -> 7510 | I23: ='DCF Valuation'!I22*Inputs!H23 -> 8638 | J23: ='DCF Valuation'!J22*Inputs!I23 -> 9083.7973 | K23: ='DCF Valuation'!K22*Inputs!J23 -> 9372.1562 | ... N23: ='DCF Valuation'!N22*Inputs!M23 -> 10301.727
B24: OpEx | D24: =D22*Inputs!C24 -> 3833 | E24: =E22*Inputs!D24 -> 3699 | F24: =F22*Inputs!E24 -> 5020 | G24: =G22*Inputs!F24 -> 5394 | H24: =H22*Inputs!G24 -> 5421 | I24: =I22*Inputs!H24 -> 6206 | J24: =J22*Inputs!I24 -> 6972.1111 | K24: =K22*Inputs!J24 -> 7193.4361 | ... N24: =N22*Inputs!M24 -> 7906.9117
B25: EBIT | D25: =D22-D23-D24 -> 3208 | E25: =E22-E23-E24 -> 3182 | F25: =F22-F23-F24 -> 4104 | G25: =G22-G23-G24 -> 5024 | H25: =H22-H23-H24 -> 4186 | I25: =I22-I23-I24 -> 5404 | J25: =J22-J23-J24 -> 3843.6086 | K25: =K22-K23-K24 -> 3965.6214 | ... N25: =N22-N23-N24 -> 4358.9486
B26: Taxes | D26: =D25*Inputs!C28 -> 292.72253 | E26: =E25*Inputs!D28 -> -404.27049 | F26: =F25*Inputs!E28 -> 3015.8977 | G26: =G25*Inputs!F28 -> -243.5102 | H26: =H25*Inputs!G28 -> 471.72183 | I26: =I25*Inputs!H28 -> 361.55219 | J26: =J25*Inputs!I28 -> 807.15781 | K26: =K25*Inputs!J28 -> 832.78048 | ... N26: =N25*Inputs!M28 -> 915.3792
B27: NOPAT | D27: =D25-D26 -> 2915.2775 | E27: =E25-E26 -> 3586.2705 | F27: =F25-F26 -> 1088.1023 | G27: =G25-G26 -> 5267.5102 | H27: =H25-H26 -> 3714.2782 | I27: =I25-I26 -> 5042.4478 | J27: =J25-J26 -> 3036.4508 | K27: =K25-K26 -> 3132.8409 | ... N27: =N25-N26 -> 3443.5694
B28: + D&A | D28: ='DCF Valuation'!D22*Inputs!C25 -> 1050 | E28: ='DCF Valuation'!E22*Inputs!D25 -> 939 | F28: ='DCF Valuation'!F22*Inputs!E25 -> 1855 | G28: ='DCF Valuation'!G22*Inputs!F25 -> 2130 | H28: ='DCF Valuation'!H22*Inputs!G25 -> 2030 | I28: ='DCF Valuation'!I22*Inputs!H25 -> 2134 | J28: ='DCF Valuation'!J22*Inputs!I25 -> 2072.882 | K28: ='DCF Valuation'!K22*Inputs!J25 -> 2138.6842 | ... N28: ='DCF Valuation'!N22*Inputs!M25 -> 2350.808
B29: - Change in NWC | D29: =D22*Inputs!C27 -> 399 | E29: =E22*Inputs!D27 -> -371 | F29: =F22*Inputs!E27 -> 897 | G29: =G22*Inputs!F27 -> -369 | H29: =H22*Inputs!G27 -> 113 | I29: =I22*Inputs!H27 -> 334 | J29: =J22*Inputs!I27 -> 196.21574 | K29: =K22*Inputs!J27 -> 202.44447 | ... N29: =N22*Inputs!M27 -> 222.52378
B30: - CAPEX | D30: =D22*Inputs!C26 -> 718 | E30: =E22*Inputs!D26 -> 727 | F30: =F22*Inputs!E26 -> 895 | G30: =G22*Inputs!F26 -> 957 | H30: =H22*Inputs!G26 -> 810 | I30: =I22*Inputs!H26 -> 1231 | J30: =J22*Inputs!I26 -> 1317.0166 | K30: =K22*Inputs!J26 -> 1564.1365 | ... N30: =N22*Inputs!M26 -> 2396.3018
B31: FCF | D31: =D27+D28-D29-D30 -> 2848.2775 | E31: =E27+E28-E29-E30 -> 4169.2705 | F31: =F27+F28-F29-F30 -> 1151.1023 | G31: =G27+G28-G29-G30 -> 6809.5102 | H31: =H27+H28-H29-H30 -> 4821.2782 | I31: =I27+I28-I29-I30 -> 5611.4478 | J31: =J27+J28-J29-J30 -> 3596.1005 | K31: =K27+K28-K29-K30 -> 3504.9441 | ... N31: =N27+N28-N29-N30 -> 3175.5518
B32: Discount Factor | J32: =1/(1+$C$11)^1 -> 0.94975563 | K32: =1/(1+$C$11)^2 -> 0.90203576 | L32: =1/(1+$C$11)^3 -> 0.85671354 | M32: =1/(1+$C$11)^4 -> 0.81366851 | N32: =1/(1+$C$11)^5 -> 0.77278625
B33: Discounted FCF | J33: =J31*J32 -> 3415.4167 | K33: =K31*K32 -> 3161.5849 | L33: =L31*L32 -> 2916.973 | M33: =M31*M32 -> 2681.231 | N33: =N31*N32 -> 2454.0227
B36: Terminal Value Calculation
B38: Terminal Value
B39: Terminal Year | C39: FY2027
B40: Terminal Cash Flow | C40: =N31*(1+C41) -> 3239.0628
B41: Terminal Growth Rate | C41: 0.02 | D41: Assumption 26
B42: Discount Rate | C42: =C11 -> 0.052902418
B43: Terminal Value | C43: =C40/(C42-C41) -> 98444.521
B44: PV of Terminal Value | C44: =C43/(1+C42)^5 -> 76076.571
B46: Value per Share
B47: Enterprise Value | C47: =SUM(J33:N33)+C44 -> 90705.8
...

Sheet Comparables
A3: Comps Tables - FactSet RBICS Sub-Sector - General Medical Devices | E3: Assumption 28
A4: Selected Financials
D5: Market Data ($) | I5: Financial ($) | L5: Valuation (x)
A6: Company | C6: Fiscal | G6: Shares Out | H6: Shares Out | L6: EV/ | M6: EV/
A7: Name | B7: Ticker | C7: Period | D7: Price | E7: Mkt Cap (M) | F7: EV (M) | G7: (M) | H7: Diluted (M) | I7: Sales (M) | J7: EBIT (M) | K7: EBITDA (M) | L7: EBIT | M7: EBITDA
A8: Becton, Dickinson | B8: BDX-US | C8: 12/31/2021 | D8: 267.60001 | E8: 76204.737 | F8: 91575.734 | G8: 284.77109 | H8: 286.723 | I8: 19927 | J8: 2815 | K8: 5090 | L8: 32.531344 | M8: 17.991303
A9: Edwards Lifesciences | B9: EW-US | C9: 12/2021 | D9: 111.55 | E9: 69518.794 | F9: 68740.797 | G9: 623.20746 | H9: 631.2 | I9: 5232.5 | J9: 1610.4 | K9: 1773.7 | L9: 42.685544 | M9: 38.755596
A10: Boston Scientific | B10: BSX-US | C10: 12/2021 | D10: 44.32 | E10: 63232.44 | F10: 70644.438 | G10: 1426.7247 | H10: 1433.8 | I10: 11888 | J10: 1922 | K10: 3015 | L10: 36.755692 | M10: 23.430992
A11: Stryker Corp | B11: SYK-US | C11: 12/2021 | D11: 265.79001 | E11: 100347.6 | F11: 110229.6 | G11: 377.54468 | H11: 382.3 | I11: 17108 | J11: 3661 | K11: 4651 | L11: 30.109151 | M11: 23.700194
A12: Intuitive Surgical | B12: ISRG-US | C12: 12/2021 | D12: 283.28 | E12: 101752.72 | F12: 97686.117 | G12: 359.19482 | H12: 365.8 | I12: 5710.1 | J12: 1821 | K12: 2138 | L12: 53.644217 | M12: 45.690421
A13: Baxter Intl | B13: BAX-US | C13: 12/2021 | D13: 79.050003 | E13: 39706.314 | F13: 55104.312 | G13: 502.29361 | H13: 508 | I13: 12784 | J13: 2083 | K13: 2973 | L13: 26.454303 | M13: 18.534919
A14: Danaher | B14: DHR-US | C14: 12/2021 | D14: 289.26999 | E14: 206930.02 | F14: 230894.02 | G14: 715.3526 | H14: 736.8 | I14: 29453 | J14: 8050 | K14: 10218 | L14: 28.682487 | M14: 22.596792
A15: Abbott Laboratories | B15: ABT-US | C15: 12/2021 | D15: 121.76 | E15: 215306.63 | F15: 224530.62 | G15: 1768.287 | H15: 1789 | I15: 43075 | J15: 9200 | K15: 12738 | L15: 24.405503 | M15: 17.626835
A16: Average | L16: 34.40853 | M16: 26.040882
A17: Median | L17: 31.320248 | M17: 23.013892
A18: Valuation
F19: P/E (x) | I19: EV/ (x) | L19: Financial ($)
A20: Company | C20: Fiscal | D20: FY1
A21: Name | B21: Ticker | C21: Period | D21: Date | E21: EV (M) | F21: Actual | G21: FY1 | H21: FY2 | I21: Sales | J21: EBIT | K21: EBITDA | L21: Sales (M) | M21: EBIT (M) | N21: EBITDA (M)
A22: Becton, Dickinson | B22: BDX-US | C22: 12/31/2021 | D22: 09/2022 | E22: 91575.734 | F22: 46.246371 | G22: 20.708977 | H22: 19.176928 | I22: 4.59556 | J22: 32.531344 | K22: 17.991303 | L22: 19927 | M22: 2815 | N22: 5090
A23: Edwards Lifesciences | B23: EW-US | C23: 12/2021 | D23: 12/2022 | E23: 68740.797 | F23: 46.844161 | G23: 43.832638 | H23: 38.795483 | I23: 13.137277 | J23: 42.685544 | K23: 38.755596 | L23: 5232.5 | M23: 1610.4 | N23: 1773.7
A24: Boston Scientific | B24: BSX-US | C24: 12/2021 | D24: 12/2022 | E24: 70644.438 | F24: 64.512373 | G24: 25.021961 | H24: 22.077976 | I24: 5.9425 | J24: 36.755692 | K24: 23.430992 | L24: 11888 | M24: 1922 | N24: 3015
A25: Stryker Corp | B25: SYK-US | C25: 12/2021 | D25: 12/2022 | E25: 110229.6 | F25: 50.958626 | G25: 27.143648 | H25: 24.251787 | I25: 6.443161 | J25: 30.109151 | K25: 23.700194 | L25: 17108 | M25: 3661 | N25: 4651
A26: Intuitive Surgical | B26: ISRG-US | C26: 12/2021 | D26: 12/2022 | E26: 97686.117 | F26: 60.791004 | G26: 56.469055 | H26: 47.832645 | I26: 17.107602 | J26: 53.644217 | K26: 45.690421 | L26: 5710.1 | M26: 1821 | N26: 2138
A27: Baxter Intl | B27: BAX-US | C27: 12/2021 | D27: 12/2022 | E27: 55104.312 | F27: 31.274727 | G27: 18.39086 | H27: 16.09816 | I27: 4.310412 | J27: 26.454303 | K27: 18.534919 | L27: 12784 | M27: 2083 | N27: 2973
A28: Danaher | B28: DHR-US | C28: 12/2021 | D28: 12/2022 | E28: 230894.02 | F28: 33.58021 | G28: 27.707012 | H28: 26.158239 | I28: 7.839406 | J28: 28.682487 | K28: 22.596792 | L28: 29453 | M28: 8050 | N28: 10218
A29: Abbott Laboratories | B29: ABT-US | C29: 12/2021 | D29: 12/2022 | E29: 224530.62 | F29: 30.932602 | G29: 25.110802 | H29: 23.737774 | I29: 5.212551 | J29: 24.405503 | K29: 17.626835 | L29: 43075 | M29: 9200 | N29: 12738
A30: Average | F30: 45.642509 | G30: 30.548119 | H30: 27.266124 | I30: 8.073559 | J30: 34.40853 | K30: 26.040882
A31: Median | F31: 46.545266 | G31: 26.127225 | H31: 23.994781 | I31: 6.19283 | J31: 31.320248 | K31: 23.013892

Sheet BDX-USA
A1: Becton, Dickinson and Company
A2: BDX 075887109 2087807 NYSE Common stock
A5: Instrument ID | B5: Description | C5: Balance Sheet Amt Out (USD) | D5: Current Amt Out (USD) | E5: Coupon Rate | F5: Coupon Type | G5: Issue Date | H5: Maturity Date | I5: Issue Curr | J5: Seniority | K5: Price | L5: YTW | M5: OAS (LIBOR)
A6: ST Debt | C6: 1064 | D6: 1064
A7: - | B7: Current Portion Of LTD | C7: 1064 | D7: 1064 | E7: - | F7: - | G7: - | H7: - | I7: USD | J7: Other | K7: - | L7: - | M7: -
A8: Revolving Credit | C8: 0 | D8: 0
A9: FDS1OTGB4 | B9: Senior Unsec. Revolving Credit Facility | C9: 0 | D9: 0 | E9: - | F9: Variable | G9: 09/2021 | H9: 09/2026 | I9: USD | J9: SNR Unsec | K9: - | L9: - | M9: - | N9: _
A10: Notes/Bonds | C10: 17509.9 | D10: 17509.9
A11: 075887BU2 | B11: Becton Dickinson & Co - FRN | C11: 500 | D11: 500 | E11: - | F11: Variable | G11: 06/2017 | H11: 06/2022 | I11: USD | J11: SNR Unsec | K11: 100.08 | L11: 1.27 | M11: 40.1 | N11: _
A12: 075887BN8 | B12: Becton Dickinson & Co - 500M EUR | C12: 568.6 | D12: 568.6 | E12: 0.01 | F12: Fixed | G12: 12/2016 | H12: 12/2022 | I12: EUR | J12: SNR Unsec | K12: 100.7 | L12: 0.06 | M12: 37.33 | N12: _
A13: 075887CH0 | B13: Becton Dickinson & Co - MTN - 300M EUR | C13: 341.2 | D13: 341.2 | E13: 0.01401 | F13: Fixed | G13: 05/2018 | H13: 05/2023 | I13: EUR | J13: SNR Unsec | K13: 101.33 | L13: 0.19 | M13: 31.33 | N13: _
A14: 075887CM9 | B14: Becton Dickinson & Co - 400M EUR | C14: 454.9 | D14: 454.9 | E14: - | F14: Fixed | G14: 08/2021 | H14: 08/2023 | I14: EUR | J14: SNR Unsec | K14: 99.43 | L14: 0.41 | M14: 37.84
A15: 07589LAB3 | B15: Becton Dickinson Euro Finance SARL - 800M EUR | C15: 909.8 | D15: 909.8 | E15: 0.00632 | F15: Fixed | G15: 06/2019 | H15: 06/2023 | I15: EUR | J15: SNR Unsec | K15: 100.58 | L15: 0.12 | M15: 19.93 | N15: _
A16: 075887BL2 | B16: Becton Dickinson & Co | C16: 143.6 | D16: 143.6 | E16: 0.03875 | F16: Fixed | G16: 04/2015 | H16: 05/2024 | I16: USD | J16: SNR Unsec | K16: 101.59 | L16: 3.01 | M16: 80.92 | N16: _
A17: 075887BF5 | B17: Becton Dickinson & Co | C17: 875 | D17: 875 | E17: 0.03734 | F17: Fixed | G17: 12/2014 | H17: 12/2024 | I17: USD | J17: SNR Unsec | K17: 102.03 | L17: 2.88 | M17: 59.02 | N17: _
A18: 075887BV0 | B18: Becton Dickinson & Co | C18: 997.7 | D18: 997.7 | E18: 0.03363 | F18: Fixed | G18: 06/2017 | H18: 06/2024 | I18: USD | J18: SNR Unsec | K18: 101.4 | L18: 2.65 | M18: 42.34
A19: 075887CG2 | B19: Becton Dickinson & Co - 250M GBP | C19: 338.6 | D19: 338.6 | E19: 0.0302 | F19: Fixed | G19: 05/2018 | H19: 05/2025 | I19: GBP | J19: SNR Unsec | K19: 101.66 | L19: 2.43 | M19: 57.91 | N19: _
A20: 075887CN7 | B20: Becton Dickinson & Co - 500M EUR | C20: 568.6 | D20: 568.6 | E20: 0.00034 | F20: Fixed | G20: 08/2021 | H20: 08/2025 | I20: EUR | J20: SNR Unsec | K20: 96.85 | L20: 0.98 | M20: 43.44 | N20: _
A21: 067383AA7 | B21: CR Bard Inc | C21: 12.8 | D21: 12.8 | E21: 0.067 | F21: Fixed | G21: 12/1996 | H21: 12/2026 | I21: USD | J21: SNR Unsec | K21: 107.32 | L21: 4.93 | M21: 269.44 | N21: _
A22: 075887CE7 | B22: Becton Dickinson & Co | C22: 134 | D22: 134 | E22: 0.067 | F22: Fixed | G22: 04/2018 | H22: 12/2026 | I22: USD | J22: SNR Unsec | K22: 114.29 | L22: 3.39 | M22: 114.65 | N22: _
A23: 075887BP3 | B23: Becton Dickinson & Co - 500M EUR | C23: 568.6 | D23: 568.6 | E23: 0.019 | F23: Fixed | G23: 12/2016 | H23: 12/2026 | I23: EUR | J23: SNR Unsec | K23: 102.97 | L23: 1.21 | M23: 52.51 | N23: _
A24: 07589LAC1 | B24: Becton Dickinson Euro Finance SARL - 600M EUR | C24: 682.3 | D24: 682.3 | E24: 0.01208 | F24: Fixed | G24: 06/2019 | H24: 06/2026 | I24: EUR | J24: SNR Unsec | K24: 100.02 | L24: 1.2 | M24: 53.93 | N24: _
A25: 075887AN9 | B25: Becton Dickinson & Co | C25: 168 | D25: 168 | E25: 0.07 | F25: Fixed | G25: 07/1997 | H25: 08/2027 | I25: USD | J25: SNR Unsec | K25: 117.89 | L25: 3.33 | M25: 110.02 | N25: _
A26: 075887BW8 | B26: Becton Dickinson & Co | C26: 1725 | D26: 1725 | E26: 0.037 | F26: Fixed | G26: 06/2017 | H26: 06/2027 | I26: USD | J26: SNR Unsec | K26: 102.53 | L26: 3.14 | M26: 88.9
A27: 075887AQ2 | B27: Becton Dickinson & Co | C27: 167.1 | D27: 167.1 | E27: 0.067 | F27: Fixed | G27: 08/1998 | H27: 08/2028 | I27: USD | J27: SNR Unsec | K27: 117.2 | L27: 3.65 | M27: 141.33 | N27: _
A28: L076BMAB2 | B28: Becton Dickinson Euro Finance SARL - 900M EUR | C28: 1023.5 | D28: 1023.5 | E28: 0.00334 | F28: Fixed | G28: 08/2021 | H28: 08/2028 | I28: EUR | J28: SNR Unsec | K28: 92.48 | L28: 1.57 | M28: 76.54 | N28: _
A29: 075887CJ6 | B29: Becton Dickinson & Co | C29: 750 | D29: 750 | E29: 0.02823 | F29: Fixed | G29: 05/2020 | H29: 05/2030 | I29: USD | J29: SNR Unsec | K29: 95.71 | L29: 3.43 | M29: 117.53 | N29: _
A30: 075887CL1 | B30: Becton Dickinson & Co | C30: 1000 | D30: 1000 | E30: 0.01957 | F30: Fixed | G30: 02/2021 | H30: 02/2031 | I30: USD | J30: SNR Unsec | K30: 89 | L30: 3.4 | M30: 114.19 | N30: _
A31: 07589LAD9 | B31: Becton Dickinson & Co - 600M EUR | C31: 682.3 | D31: 682.3 | E31: 0.01213 | F31: Fixed | G31: 02/2021 | H31: 02/2036 | I31: EUR | J31: SNR Unsec | K31: 88.1 | L31: 2.2 | M31: 108.15 | N31: _
A32: 075887AV1 | B32: Becton Dickinson & Co | C32: 250 | D32: 250 | E32: 0.06 | F32: Fixed | G32: 05/2009 | H32: 05/2039 | I32: USD | J32: SNR Unsec | K32: 119.82 | L32: 4.35 | M32: 202.37 | N32: _
A33: 075887AX7 | B33: Becton Dickinson & Co | C33: 125 | D33: 125 | E33: 0.05 | F33: Fixed | G33: 11/2010 | H33: 11/2040 | I33: USD | J33: SNR Unsec | K33: 108.32 | L33: 4.34 | M33: 201.12 | N33: _
A34: L076BMAA4 | B34: Becton Dickinson Euro Finance SARL - 900M EUR | C34: 1023.5 | D34: 1023.5 | E34: 0.01336 | F34: Fixed | G34: 08/2021 | H34: 08/2041 | I34: EUR | J34: SNR Unsec | K34: 82.4 | L34: 2.48 | M34: 136.79 | N34: _
A35: 075887BM0 | B35: Becton Dickinson & Co | C35: 224.9 | D35: 224.9 | E35: 0.04875 | F35: Fixed | G35: 04/2015 | H35: 05/2044 | I35: USD | J35: SNR Unsec | K35: 108.04 | L35: 4.3 | M35: 196.74 | N35: _
A36: 075887BG3 | B36: Becton Dickinson & Co | C36: 1025 | D36: 1025 | E36: 0.04685 | F36: Fixed | G36: 12/2014 | H36: 12/2044 | I36: USD | J36: SNR Unsec | K36: 107.85 | L36: 4.14 | M36: 181.1
A37: 075887BX6 | B37: Becton Dickinson & Co | C37: 1500 | D37: 1500 | E37: 0.04669 | F37: Fixed | G37: 06/2017 | H37: 06/2047 | I37: USD | J37: SNR Unsec | K37: 108.67 | L37: 4.11 | M37: 179.48
A38: 075887CK3 | B38: Becton Dickinson & Co | C38: 750 | D38: 750 | E38: 0.03794 | F38: Fixed | G38: 05/2020 | H38: 05/2050 | I38: USD | J38: SNR Unsec | K38: 95.38 | L38: 4.07 | M38: 178.11 | N38: _
A39: Other | C39: -85.9 | D39: -85.9
A40: - | B40: Unamortized Issuance Costs - Senior Unsecured Notes | C40: -85.9 | D40: -85.9 | E40: - | F40: - | G40: - | H40: - | I40: USD | J40: Other | K40: - | L40: - | M40: -
B41: LT Debt Total | C41: 17424
B42: Current Portion of LTD | C42: -1064
...

Sheet Cost of Debt
A1: Becton, Dickinson and Company | C1: Book Value | D1: Price(as % of par) | E1: Market Value | F1: MV percentage of Total Debt | G1: YTW(%)
A2: BDX 075887109 2087807 NYSE Common stock
A5: Instrument ID
A6: ST Debt | C6: 1064 | D6: - | E6: =C6 -> 1064 | F6: =E6/$E$41 -> 0.057450485 | G6: 0 | H6: =F6*G6 -> 0
A8: Notes/Bonds
A9: 075887BU2 | C9: 500 | D9: 100.08 | E9: =C9*(D9/100) -> 500.4 | F9: =E9/$E$41 -> 0.027019006 | G9: 1.27 | H9: =F9*G9 -> 0.034314138
A10: 075887BN8 | C10: 568.6 | D10: 100.7 | E10: =C10*(D10/100) -> 572.5802 | F10: =E10/$E$41 -> 0.030916363 | G10: 0.06 | H10: =F10*G10 -> 0.0018549818
A11: 075887CH0 | C11: 341.2 | D11: 101.33 | E11: =C11*(D11/100) -> 345.73796 | F11: =E11/$E$41 -> 0.018668058 | G11: 0.19 | H11: =F11*G11 -> 0.003546931
A12: 075887CM9 | C12: 454.9 | D12: 99.43 | E12: =C12*(D12/100) -> 452.30707 | F12: =E12/$E$41 -> 0.024422237 | G12: 0.41 | H12: =F12*G12 -> 0.010013117
A13: 07589LAB3 | C13: 909.8 | D13: 100.58 | E13: =C13*(D13/100) -> 915.07684 | F13: =E13/$E$41 -> 0.049409406 | G13: 0.12 | H13: =F13*G13 -> 0.0059291287
A14: 075887BL2 | C14: 143.6 | D14: 101.59 | E14: =C14*(D14/100) -> 145.88324 | F14: =E14/$E$41 -> 0.0078769387 | G14: 3.01 | H14: =F14*G14 -> 0.023709586
A15: 075887BF5 | C15: 875 | D15: 102.03 | E15: =C15*(D15/100) -> 892.7625 | F15: =E15/$E$41 -> 0.048204547 | G15: 2.88 | H15: =F15*G15 -> 0.1388291
A16: 075887BV0 | C16: 997.7 | D16: 101.4 | E16: =C16*(D16/100) -> 1011.6678 | F16: =E16/$E$41 -> 0.054624817 | G16: 2.65 | H16: =F16*G16 -> 0.14475577
A17: 075887CG2 | C17: 338.6 | D17: 101.66 | E17: =C17*(D17/100) -> 344.22076 | F17: =E17/$E$41 -> 0.018586137 | G17: 2.43 | H17: =F17*G17 -> 0.045164312
A18: 075887CN7 | C18: 568.6 | D18: 96.85 | E18: =C18*(D18/100) -> 550.6891 | F18: =E18/$E$41 -> 0.029734357 | G18: 0.98 | H18: =F18*G18 -> 0.02913967
A19: 067383AA7 | C19: 12.8 | D19: 107.32 | E19: =C19*(D19/100) -> 13.73696 | F19: =E19/$E$41 -> 0.00074172463 | G19: 4.93 | H19: =F19*G19 -> 0.0036567024
A20: 075887CE7 | C20: 134 | D20: 114.29 | E20: =C20*(D20/100) -> 153.1486 | F20: =E20/$E$41 -> 0.0082692305 | G20: 3.39 | H20: =F20*G20 -> 0.028032691
... A36: 075887CK3 | C36: 750 | D36: 95.38 | E36: =C36*(D36/100) -> 715.35 | F36: =E36/$E$41 -> 0.038625192 | G36: 4.07 | H36: =F36*G36 -> 0.15720453
A37: Other | C37: -85.9
A38: - | C38: -85.9
B39: LT Debt Total | E39: =SUM(E9:E36) -> 17456.296 | F39: =SUM(F6:F36) -> 1
B40: ST Debt Total | E40: =E6 -> 1064 | G40: Cost of debt | H40: =SUM(H9:H36) -> 2.4109514
B41: Total Debt | E41: =E40+E39 -> 18520.296

Sheet Cost of Equity
A1: Date | B1: Open | C1: High | D1: Low | E1: Close | F1: Adj Close | G1: Volume | H1: Return for Beckton dickinson | J1: Date | K1: Open | L1: High | M1: Low | N1: Close* | O1: Adj Close** | P1: Volume | R1: Return for Beckton dickinson | S1: Market Return
A2: 42826 | B2: 184 | C2: 187.2 | D2: 175.66 | E2: 186.97 | F2: 174.96549 | G2: 31303400 | H2: =(F3-F2)/F2 -> 0.012087515 | J2: 42826 | K2: 2362.34 | L2: 2398.16 | M2: 2328.95 | N2: 2384.2 | O2: 2384.2 | P2: 65265670000 | R2: 0.012087515 | S2: =(O3-O2)/O2 -> 0.01157621 | W2: SUMMARY OUTPUT
A3: 42856 | B3: 186.38001 | C3: 190.71001 | D3: 177.64 | E3: 189.23 | F3: 177.08038 | G3: 59044400 | H3: =(F4-F3)/F3 -> 0.031073301 | J3: 42856 | K3: 2388.5 | L3: 2418.71 | M3: 2352.72 | N3: 2411.8 | O3: 2411.8 | P3: 79607170000 | R3: 0.031073301 | S3: =(O4-O3)/O3 -> 0.004813832
A4: 42887 | B4: 188.36999 | C4: 196.59 | D4: 188.3 | E4: 195.11 | F4: 182.58285 | G4: 31272500 | H4: =(F5-F4)/F4 -> 0.036180013 | J4: 42887 | K4: 2415.65 | L4: 2453.82 | M4: 2405.7 | N4: 2423.41 | O4: 2423.41 | P4: 81002490000 | R4: 0.036180013 | S4: =(O5-O4)/O4 -> 0.019348769 | W4: Regression Statistics
A5: 42917 | B5: 195.78999 | C5: 206.63001 | D5: 194.22 | E5: 201.39999 | F5: 189.1887 | G5: 22497400 | H5: =(F6-F5)/F5 -> -0.0097319288 | J5: 42917 | K5: 2431.39 | L5: 2484.04 | M5: 2407.7 | N5: 2470.3 | O5: 2470.3 | P5: 63169400000 | R5: -0.0097319288 | S5: =(O6-O5)/O5 -> 0.00054649233 | W5: Multiple R | X5: 0.48193512
A6: 42948 | B6: 201.7 | C6: 202.89999 | D6: 192.34 | E6: 199.44 | F6: 187.34753 | G6: 25729600 | H6: =(F7-F6)/F6 -> -0.017498848 | J6: 42948 | K6: 2477.1 | L6: 2490.87 | M6: 2417.35 | N6: 2471.65 | O6: 2471.65 | P6: 70616030000 | R6: -0.017498848 | S6: =(O7-O6)/O6 -> 0.019302895 | W6: R Square | X6: 0.23226146
A7: 42979 | B7: 199.44 | C7: 204.86 | D7: 191.53 | E7: 195.95 | F7: 184.06917 | G7: 23085100 | H7: =(F8-F7)/F7 -> 0.06883074 | J7: 42979 | K7: 2474.42 | L7: 2519.44 | M7: 2446.55 | N7: 2519.36 | O7: 2519.36 | P7: 66337980000 | R7: 0.06883074 | S7: =(O8-O7)/O7 -> 0.022188175 | W7: Adjusted R Square | X7: 0.21902458
A8: 43009 | B8: 196.91 | C8: 214.72 | D8: 193.05 | E8: 208.67 | F8: 196.73879 | G8: 25966300 | H8: =(F9-F8)/F8 -> 0.093640712 | J8: 43009 | K8: 2521.2 | L8: 2582.98 | M8: 2520.4 | N8: 2575.26 | O8: 2575.26 | P8: 70871570000 | R8: 0.093640712 | S8: =(O9-O8)/O8 -> 0.028082601 | W8: Standard Error | X8: 0.055500731
A9: 43040 | B9: 207.53 | C9: 228.8 | D9: 203.99 | E9: 228.21001 | F9: 215.16154 | G9: 26588300 | H9: =(F10-F9)/F9 -> -0.062004379 | J9: 43040 | K9: 2583.21 | L9: 2657.74 | M9: 2557.45 | N9: 2647.58 | O9: 2647.58 | P9: 73173260000 | R9: -0.062004379 | S9: =(O10-O9)/O9 -> 0.0098316198 | W9: Observations | X9: 60
A10: 43070 | B10: 228.27 | C10: 229.69 | D10: 213.95 | E10: 214.06 | F10: 201.82059 | G10: 25016300 | H10: =(F11-F10)/F10 -> 0.13881708 | J10: 43070 | K10: 2645.1 | L10: 2694.97 | M10: 2605.52 | N10: 2673.61 | O10: 2673.61 | P10: 65251190000 | R10: 0.13881708 | S10: =(O11-O10)/O10 -> 0.056178725
A11: 43101 | B11: 215.09 | C11: 248.39 | D11: 215.09 | E11: 242.94 | F11: 229.83673 | G11: 31718400 | H11: =(F12-F11)/F11 -> -0.086112006 | J11: 43101 | K11: 2683.73 | L11: 2872.87 | M11: 2682.36 | N11: 2823.81 | O11: 2823.81 | P11: 76860120000 | R11: -0.086112006 | S11: =(O12-O11)/O11 -> -0.03894738 | W11: ANOVA
A12: 43132 | B12: 241.08 | C12: 243.51 | D12: 209.91 | E12: 222.02 | F12: 210.04503 | G12: 29950400 | H12: =(F13-F12)/F12 -> -0.0239617 | J12: 43132 | K12: 2816.45 | L12: 2835.96 | M12: 2532.69 | N12: 2713.83 | O12: 2713.83 | P12: 79579410000 | R12: -0.0239617 | S12: =(O13-O12)/O12 -> -0.026884514 | X12: df | Y12: SS | Z12: MS | AA12: F | AB12: Significance F
A13: 43160 | B13: 221.60001 | C13: 227.8 | D13: 210.39 | E13: 216.7 | F13: 205.01199 | G13: 25411700 | H13: =(F14-F13)/F13 -> 0.073680085 | J13: 43160 | K13: 2715.22 | L13: 2801.9 | M13: 2585.89 | N13: 2640.87 | O13: 2640.87 | P13: 76369800000 | R13: 0.073680085 | S13: =(O14-O13)/O13 -> 0.002718801 | W13: Regression | X13: 1 | Y13: 0.054049191 | Z13: 0.054049191 | AA13: 17.546552 | AB13: 9.6648145e-05
A14: 43191 | B14: 215.99 | C14: 236.13001 | D14: 210.21001 | E14: 231.86999 | F14: 220.11729 | G14: 23710200 | H14: =(F15-F14)/F14 -> -0.044335394 | J14: 43191 | K14: 2633.45 | L14: 2717.49 | M14: 2553.8 | N14: 2648.05 | O14: 2648.05 | P14: 69648590000 | R14: -0.044335394 | S14: =(O15-O14)/O14 -> 0.021608353 | W14: Residual | X14: 58 | Y14: 0.17865921 | Z14: 0.0030803311
